I'm sorry, but an uncaught exception occurred.

While running game code:
NameError: name 'e' is not defined

During handling of the above exception, another exception occurred:

Traceback (most recent call last):
  File "game/script.rpy", line 247, in script
    e "您已创建了一个新的 Ren'Py 游戏。"
Exception: Sayer 'e' is not defined.

-- Full Traceback ------------------------------------------------------------

Traceback (most recent call last):
  File "renpy/ast.py", line 625, in eval_who
    return renpy.python.py_eval(who)
           ~~~~~~~~~~~~~~~~~~~~^^^^^
  File "renpy/python.py", line 1292, in py_eval
    return py_eval_bytecode(code, globals, locals)
           ~~~~~~~~~~~~~~~~^^^^^^^^^^^^^^^^^^^^^^^
  File "renpy/python.py", line 1285, in py_eval_bytecode
    return eval(bytecode, globals, locals)
           ~~~~^^^^^^^^^^^^^^^^^^^^^^^^^^^
  File "<none>", line 1, in <module>
NameError: name 'e' is not defined

During handling of the above exception, another exception occurred:

Traceback (most recent call last):
  File "game/script.rpy", line 247, in script
    e "您已创建了一个新的 Ren'Py 游戏。"
  File "renpy/ast.py", line 2915, in execute
    Say.execute(self)
    ~~~~~~~~~~~^^^^^^
  File "renpy/ast.py", line 956, in execute
    who = eval_who(self.who, self.who_fast)
          ~~~~~~~~^^^^^^^^^^^^^^^^^^^^^^^^^
  File "renpy/ast.py", line 627, in eval_who
    raise Exception("Sayer '%s' is not defined." % who)
Exception: Sayer 'e' is not defined.

Linux-6.16.7-arch1-1-x86_64-with-glibc2.42 x86_64
Ren'Py 8.4.1.25072401
renpy_llm 1.0
Sat Sep 20 08:44:32 2025
